<mujoco model="WalkON5">
    <compiler inertiafromgeom="false" angle="degree" balanceinertia = "true"/>
    <default>
        <joint limited="true" damping="1" armature="0"/>
        <geom condim="1" material="matgeom"/>
    </default>
    <option timestep=".005" iterations="50" tolerance="1e-16" solver="Newton" jacobian="dense" cone="pyramidal">
        <flag contact="enable"/>
    </option>
    <size nconmax="50" njmax="500" nstack="10000"/>
    <visual>
        <map force="0.1" zfar="30"/>
        <rgba haze="0.35 0.35 0.35 1"/>
        <quality shadowsize="2048"/>
        <global offwidth="1200" offheight="960"/>
    </visual>
    <asset>
        <texture type="skybox" builtin="gradient" rgb1="0.3 0.5 0.7" rgb2="0 0 0" width="512" height="512"/>
        <texture name="texplane" type="2d" builtin="checker" rgb1=".2 .3 .4" rgb2=".1 0.15 0.2" width="512" height="512" mark="cross" markrgb=".8 .8 .8"/>
        <texture name="texgeom" type="cube" builtin="flat" mark="cross" width="127" height="1278"
            rgb1="0.8 0.8 0.8" rgb2="0.6 0.6 0.6" markrgb="1 1 1" random="0.01"/>
        <material name="matplane" reflectance="0.3" texture="texplane" texrepeat="1 1" texuniform="true"/>
        <material name="matgeom" texture="texgeom" texuniform="true" rgba="0.8 0.8 0.8 1"/>
        <mesh name="BASE" file="../walkon_stls/BASE.STL"/>
        <mesh name="L_BASE" file="../new_stls/L_BASE.STL"/>
        <mesh name="L_HIP" file="../new_stls/L_HIP.STL"/>
        <mesh name="L_THIGH" file="../new_stls/L_THIGH.STL"/>
        <mesh name="L_SHANK" file="../new_stls/L_SHANK.STL"/>
        <mesh name="L_ANKLE" file="../new_stls/L_ANKLE.STL"/>
        <mesh name="L_FOOT" file="../new_stls/L_FOOT.STL"/>
    </asset>
    <worldbody>
        <geom name="floor" pos="0 0 0" size="0 0 .25" type="plane" material="matplane" condim="3"/>
        <light name="light" pos="0 5 5"/>


        <!-- <body name="BASE" pos="0 0 1.2">
            <freejoint/>
            <geom type="mesh" mesh="BASE" pos="0 0 0"/>
            <inertial mass="4.06288" pos="0.08148 0.14026 0.0055"/> -->
            
            <!-- <body name="L_BASE" pos="0 0 1.17">
                <joint name="JOINT_LH_ABD" pos="0 .115 0" axis="1 0 0" range="-10 15"/>
                <geom type="mesh" mesh="L_BASE"/>
                <inertial mass="4.90278" pos="-0.07981 0.24120 0.00173" fullinertia="0.02121140274 0.04835300896 0.05130374593 -0.00991849754 0.01321543313 -0.00272525179"/>
                <body name="L_HIP" pos="0 0 0">
                    <joint name="JOINT_LH_ROT" pos="-.1875 .2705 .0" axis="0 0 1" range="0 0.01" damping="5.65"/>
                    <geom type="mesh" mesh="L_HIP"/>
                    <inertial mass="4.36022" pos="-0.23011 0.27290 -0.15211" fullinertia="0.02481750877 0.03327195800 0.01078873999 -0.00006698203 -0.00658768434 -0.00021012633"/>
                    <body name="L_THIGH" pos="0 0 0">
                        <joint name="JOINT_LH_EXT" pos="-.1875 .2405 -.16915" axis="0 -1 0" range="0 0.01" damping="3.25"/>
                        <geom type="mesh" mesh="L_THIGH"/>
                        <inertial mass="2.70534" pos="-0.23622 0.26194 -0.46966" fullinertia="0.05534355638 0.05728662078 0.00657494103 0.00003076713 -0.00158568371 0.00567343673"/> -->
                        <body name="L_SHANK" pos="0 0 1.2">
                            <freejoint/>
                            <!-- <joint name="JOINT_LK_EXT" pos="-.1875 .21426 -.59977" axis="0 1 0" range="0 0.1" damping="3"/> -->
                            <geom type="mesh" mesh="L_SHANK"/>
                            <inertial mass="2.49032" pos="-0.11729 0.15565 -0.73073" fullinertia="0.03393903802 0.03098446128 0.00742201881 -0.00247943357 -0.00384162992 0.00441951882"/>
                            <body name="L_ANKLE" pos="0 0.05 0" euler="0 0 0">
                                <!-- <joint name="JOINT_LA_INV" pos="-.06603 .10476 -.90801" axis="1 0 1" range="-170 170"/> -->
                                <joint name="JOINT_LA_INV" pos="-.06603 .10476 -.90801" axis="1 0 1" range="0 0.01"/>
                                <geom type="mesh" mesh="L_ANKLE"/>
                                <inertial mass="0.55947" pos="-0.11980 0.13526 -0.95381" fullinertia="0.00291884244 0.00128487003 0.00290532896 0.00000005 0.00054856466 0.00000000"/>
                                <body name="L_FOOT" pos="0 0 0" euler="0 0 0">
                                    <joint name="JOINT_LA_PLA" pos="-.15552 .17526 -.9975" axis="0 -1 0" range="-170 170"/>
                                    <!-- <joint name="JOINT_LA_PLA" pos="-.15552 .17526 -.9975" axis="0 -1 0" range="0 0.01"/> -->
                                    <geom type="mesh" mesh="L_FOOT" priority="1" solimp="0.015 1 0.023" condim="3" friction="0.9 0.9 0.01"/>
                                    <inertial mass="7.55104" pos="-0.06324 0.13721 -0.97385" fullinertia="0.19865487853 0.21838580395 0.07110140611 -0.00052461653 0.01985821394 -0.00159785996"/>
                                </body>
                            </body>
                        </body>
                    <!-- </body>
                </body>
            </body> -->
        <!-- </body> -->
    </worldbody>

    <actuator>
        <!-- LEFT LIMB ACTUATORS -->
        <!-- <general name="ACT_L_HIP_ABD" joint="JOINT_LH_ABD" gear="1" ctrllimited="true" ctrlrange="-250 250"/> -->
        <!-- <general name="ACT_L_HIP_ROT" joint="JOINT_LH_ROT" gear="1" ctrllimited="true" ctrlrange="-135 135"/>
        <general name="ACT_L_HIP_EXT" joint="JOINT_LH_EXT" gear="1" ctrllimited="true" ctrlrange="-200 200"/>
        <general name="ACT_L_KNEE_EXT" joint="JOINT_LK_EXT" gear="1" ctrllimited="true" ctrlrange="-200 200"/> -->
        <general name="ACT_L_ANK_INVER" joint="JOINT_LA_INV" gear="1" ctrllimited="true" ctrlrange="-70 70"/>
        <general name="ACT_L_ANK_PLANTAR" joint="JOINT_LA_PLA" gear="1" ctrllimited="true" ctrlrange="-170 170"/>

    </actuator>

    <!-- <actuator> -->
        <!-- LEFT LIMB ACTUATORS -->
        <!-- <general name="ACT_L_HIP_ABD" joint="JOINT_LH_ABD" gear="1" ctrllimited="false"/>
        <general name="ACT_L_HIP_ROT" joint="JOINT_LH_ROT" gear="1" ctrllimited="false"/>
        <general name="ACT_L_HIP_EXT" joint="JOINT_LH_EXT" gear="1" ctrllimited="false"/>
        <general name="ACT_L_KNEE_EXT" joint="JOINT_LK_EXT" gear="1" ctrllimited="false"/>
        <general name="ACT_L_ANK_INVER" joint="JOINT_LA_INV" gear="1" ctrllimited="false"/>
        <general name="ACT_L_ANK_PLANTAR" joint="JOINT_LA_PLA" gear="1" ctrllimited="false"/> -->
    <!-- </actuator> -->

</mujoco>

