<!-- https://mujoco.readthedocs.io/en/latest/overview.html?highlight=hello.xml#examples -->
<mujoco>
  <compiler inertiafromgeom="true" angle="degree" autolimits="true"/>
  <default>
    <!-- <joint limited="true" damping="1" armature="0"/> -->
    <!-- <geom condim="1" material="matgeom"/> -->
  </default>
  <option timestep=".005" iterations="50" tolerance="1e-16" solver="Newton" jacobian="dense" cone="pyramidal">
    <flag contact="enable"/>
  </option>
  <!-- <option gravity = "0 0 -9.81" /> -->
   <worldbody>
      <light diffuse="0 0 0" pos="0 0 10" dir="0 0 -1"/>
      <body pos="0 0 0" euler="0 180 0">
         <joint name="joint0" type="hinge" axis = "0 -1 0" pos = "0 0 0.5"/>
         <geom type="cylinder" size="0.05 0.5" rgba="1 0 0 1" mass="1"/>
         <body pos="0 -0.1 -1" euler="0 0 0">
           <joint name="joint1" type="hinge" axis = "0 -1 0" pos = "0 0 0.5"/>
           <geom type="cylinder" size="0.05 0.5" rgba="0 1 0 1" mass="1"/>
         </body>
      </body>
    </worldbody>
   <actuator>
     <motor name="torque0" joint="joint0"  gear="1" />
     <motor name="torque1" joint="joint1"  gear="1" />
   </actuator>
</mujoco>
